Training:  dbsr  model-8_synthetic
train dataset length:  300
val dataset length:  81
basetrainer's device:  cuda:2
!!!!!!!!!!!!!!!!net's device:  cuda:2
No matching checkpoint file found
!!!!!!!!!!!!!!!!!!!!data's device:  cuda:2
net's device:  cuda:2
net's device!!!!!!!!!!!!!:  cuda:2
Training crashed at epoch 1
Traceback for the error!
Traceback (most recent call last):
  File "/home/yutong/zheng/projects/DBSR/trainers/base_trainer.py", line 71, in train
    self.train_epoch()
  File "/home/yutong/zheng/projects/DBSR/trainers/simple_trainer.py", line 96, in train_epoch
    self.cycle_dataset(loader)
  File "/home/yutong/zheng/projects/DBSR/trainers/simple_trainer.py", line 76, in cycle_dataset
    loss, stats = self.actor(data)
  File "/home/yutong/zheng/projects/DBSR/actors/dbsr_actors.py", line 30, in __call__
    pred, aux_dict = self.net(data['burst'])
  File "/home/yutong/anaconda3/envs/dbsr/lib/python3.8/site-packages/torch/nn/modules/module.py", line 1130, in _call_impl
    return forward_call(*input, **kwargs)
  File "/home/yutong/zheng/projects/DBSR/models/dbsr/dbsrnet.py", line 34, in forward
    out_enc = self.encoder(im)
  File "/home/yutong/anaconda3/envs/dbsr/lib/python3.8/site-packages/torch/nn/modules/module.py", line 1130, in _call_impl
    return forward_call(*input, **kwargs)
  File "/home/yutong/zheng/projects/DBSR/models/dbsr/encoders.py", line 61, in forward
    offsets = self.alignment_net(x_oth.view(-1, *x_oth.shape[-3:]), x_ref.view(-1, *x_ref.shape[-3:]))
  File "/home/yutong/anaconda3/envs/dbsr/lib/python3.8/site-packages/torch/nn/modules/module.py", line 1130, in _call_impl
    return forward_call(*input, **kwargs)
  File "/home/yutong/zheng/projects/DBSR/models/alignment/pwcnet.py", line 280, in forward
    flow = self.net(target_img_re, source_img_re)
  File "/home/yutong/anaconda3/envs/dbsr/lib/python3.8/site-packages/torch/nn/modules/module.py", line 1130, in _call_impl
    return forward_call(*input, **kwargs)
  File "/home/yutong/zheng/projects/DBSR/models/alignment/pwcnet.py", line 228, in forward
    objEstimate = self.netSix(tenFirst[-1], tenSecond[-1], None)
  File "/home/yutong/anaconda3/envs/dbsr/lib/python3.8/site-packages/torch/nn/modules/module.py", line 1130, in _call_impl
    return forward_call(*input, **kwargs)
  File "/home/yutong/zheng/projects/DBSR/models/alignment/pwcnet.py", line 164, in forward
    tenVolume = torch.nn.functional.leaky_relu(input=correlation.FunctionCorrelation(tenFirst=tenFirst, tenSecond=tenSecond), negative_slope=0.1, inplace=False)
  File "/home/yutong/zheng/projects/DBSR/external/pwcnet/correlation/correlation.py", line 387, in FunctionCorrelation
    return _FunctionCorrelation.apply(tenFirst, tenSecond)
  File "/home/yutong/zheng/projects/DBSR/external/pwcnet/correlation/correlation.py", line 294, in forward
    cupy_launch('kernel_Correlation_rearrange', cupy_kernel('kernel_Correlation_rearrange', {
  File "cupy/cuda/function.pyx", line 224, in cupy.cuda.function.Function.__call__
  File "cupy/cuda/function.pyx", line 206, in cupy.cuda.function._launch
  File "cupy_backends/cuda/api/driver.pyx", line 253, in cupy_backends.cuda.api.driver.launchKernel
  File "cupy_backends/cuda/api/driver.pyx", line 60, in cupy_backends.cuda.api.driver.check_status
cupy_backends.cuda.api.driver.CUDADriverError: CUDA_ERROR_ILLEGAL_ADDRESS: an illegal memory access was encountered

Restarting training from last epoch ...
No matching checkpoint file found
!!!!!!!!!!!!!!!!!!!!data's device:  cuda:2
Training crashed at epoch 1
Traceback for the error!
Traceback (most recent call last):
  File "/home/yutong/zheng/projects/DBSR/trainers/base_trainer.py", line 71, in train
    self.train_epoch()
  File "/home/yutong/zheng/projects/DBSR/trainers/simple_trainer.py", line 96, in train_epoch
    self.cycle_dataset(loader)
  File "/home/yutong/zheng/projects/DBSR/trainers/simple_trainer.py", line 70, in cycle_dataset
    data = data.to(self.device)
  File "/home/yutong/zheng/projects/DBSR/admin/tensordict.py", line 20, in apply_attr
    return TensorDict({n: getattr(e, name)(*args, **kwargs) if hasattr(e, name) else e for n, e in self.items()})
  File "/home/yutong/zheng/projects/DBSR/admin/tensordict.py", line 20, in <dictcomp>
    return TensorDict({n: getattr(e, name)(*args, **kwargs) if hasattr(e, name) else e for n, e in self.items()})
RuntimeError: CUDA error: an illegal memory access was encountered

Restarting training from last epoch ...
No matching checkpoint file found
!!!!!!!!!!!!!!!!!!!!data's device:  cuda:2
Training crashed at epoch 1
Traceback for the error!
Traceback (most recent call last):
  File "/home/yutong/zheng/projects/DBSR/trainers/base_trainer.py", line 71, in train
    self.train_epoch()
  File "/home/yutong/zheng/projects/DBSR/trainers/simple_trainer.py", line 96, in train_epoch
    self.cycle_dataset(loader)
  File "/home/yutong/zheng/projects/DBSR/trainers/simple_trainer.py", line 70, in cycle_dataset
    data = data.to(self.device)
  File "/home/yutong/zheng/projects/DBSR/admin/tensordict.py", line 20, in apply_attr
    return TensorDict({n: getattr(e, name)(*args, **kwargs) if hasattr(e, name) else e for n, e in self.items()})
  File "/home/yutong/zheng/projects/DBSR/admin/tensordict.py", line 20, in <dictcomp>
    return TensorDict({n: getattr(e, name)(*args, **kwargs) if hasattr(e, name) else e for n, e in self.items()})
RuntimeError: CUDA error: an illegal memory access was encountered

Restarting training from last epoch ...
No matching checkpoint file found
!!!!!!!!!!!!!!!!!!!!data's device:  cuda:2
Training crashed at epoch 1
Traceback for the error!
Traceback (most recent call last):
  File "/home/yutong/zheng/projects/DBSR/trainers/base_trainer.py", line 71, in train
    self.train_epoch()
  File "/home/yutong/zheng/projects/DBSR/trainers/simple_trainer.py", line 96, in train_epoch
    self.cycle_dataset(loader)
  File "/home/yutong/zheng/projects/DBSR/trainers/simple_trainer.py", line 70, in cycle_dataset
    data = data.to(self.device)
  File "/home/yutong/zheng/projects/DBSR/admin/tensordict.py", line 20, in apply_attr
    return TensorDict({n: getattr(e, name)(*args, **kwargs) if hasattr(e, name) else e for n, e in self.items()})
  File "/home/yutong/zheng/projects/DBSR/admin/tensordict.py", line 20, in <dictcomp>
    return TensorDict({n: getattr(e, name)(*args, **kwargs) if hasattr(e, name) else e for n, e in self.items()})
RuntimeError: CUDA error: an illegal memory access was encountered

Restarting training from last epoch ...
No matching checkpoint file found
!!!!!!!!!!!!!!!!!!!!data's device:  cuda:2
Training crashed at epoch 1
Traceback for the error!
Traceback (most recent call last):
  File "/home/yutong/zheng/projects/DBSR/trainers/base_trainer.py", line 71, in train
    self.train_epoch()
  File "/home/yutong/zheng/projects/DBSR/trainers/simple_trainer.py", line 96, in train_epoch
    self.cycle_dataset(loader)
  File "/home/yutong/zheng/projects/DBSR/trainers/simple_trainer.py", line 70, in cycle_dataset
    data = data.to(self.device)
  File "/home/yutong/zheng/projects/DBSR/admin/tensordict.py", line 20, in apply_attr
    return TensorDict({n: getattr(e, name)(*args, **kwargs) if hasattr(e, name) else e for n, e in self.items()})
  File "/home/yutong/zheng/projects/DBSR/admin/tensordict.py", line 20, in <dictcomp>
    return TensorDict({n: getattr(e, name)(*args, **kwargs) if hasattr(e, name) else e for n, e in self.items()})
RuntimeError: CUDA error: an illegal memory access was encountered

Restarting training from last epoch ...
No matching checkpoint file found
!!!!!!!!!!!!!!!!!!!!data's device:  cuda:2
Training crashed at epoch 1
Traceback for the error!
Traceback (most recent call last):
  File "/home/yutong/zheng/projects/DBSR/trainers/base_trainer.py", line 71, in train
    self.train_epoch()
  File "/home/yutong/zheng/projects/DBSR/trainers/simple_trainer.py", line 96, in train_epoch
    self.cycle_dataset(loader)
  File "/home/yutong/zheng/projects/DBSR/trainers/simple_trainer.py", line 70, in cycle_dataset
    data = data.to(self.device)
  File "/home/yutong/zheng/projects/DBSR/admin/tensordict.py", line 20, in apply_attr
    return TensorDict({n: getattr(e, name)(*args, **kwargs) if hasattr(e, name) else e for n, e in self.items()})
  File "/home/yutong/zheng/projects/DBSR/admin/tensordict.py", line 20, in <dictcomp>
    return TensorDict({n: getattr(e, name)(*args, **kwargs) if hasattr(e, name) else e for n, e in self.items()})
RuntimeError: CUDA error: an illegal memory access was encountered

Restarting training from last epoch ...
No matching checkpoint file found
Training crashed at epoch 1
Traceback for the error!
Traceback (most recent call last):
  File "/home/yutong/zheng/projects/DBSR/trainers/base_trainer.py", line 71, in train
    self.train_epoch()
  File "/home/yutong/zheng/projects/DBSR/trainers/simple_trainer.py", line 96, in train_epoch
    self.cycle_dataset(loader)
  File "/home/yutong/zheng/projects/DBSR/trainers/simple_trainer.py", line 66, in cycle_dataset
    for i, data in enumerate(loader, 1):
  File "/home/yutong/anaconda3/envs/dbsr/lib/python3.8/site-packages/torch/utils/data/dataloader.py", line 444, in __iter__
    return self._get_iterator()
  File "/home/yutong/anaconda3/envs/dbsr/lib/python3.8/site-packages/torch/utils/data/dataloader.py", line 390, in _get_iterator
    return _MultiProcessingDataLoaderIter(self)
  File "/home/yutong/anaconda3/envs/dbsr/lib/python3.8/site-packages/torch/utils/data/dataloader.py", line 1077, in __init__
    w.start()
  File "/home/yutong/anaconda3/envs/dbsr/lib/python3.8/multiprocessing/process.py", line 121, in start
    self._popen = self._Popen(self)
  File "/home/yutong/anaconda3/envs/dbsr/lib/python3.8/multiprocessing/context.py", line 224, in _Popen
    return _default_context.get_context().Process._Popen(process_obj)
  File "/home/yutong/anaconda3/envs/dbsr/lib/python3.8/multiprocessing/context.py", line 284, in _Popen
    return Popen(process_obj)
  File "/home/yutong/anaconda3/envs/dbsr/lib/python3.8/multiprocessing/popen_spawn_posix.py", line 32, in __init__
    super().__init__(process_obj)
  File "/home/yutong/anaconda3/envs/dbsr/lib/python3.8/multiprocessing/popen_fork.py", line 19, in __init__
    self._launch(process_obj)
  File "/home/yutong/anaconda3/envs/dbsr/lib/python3.8/multiprocessing/popen_spawn_posix.py", line 58, in _launch
    self.pid = util.spawnv_passfds(spawn.get_executable(),
  File "/home/yutong/anaconda3/envs/dbsr/lib/python3.8/multiprocessing/util.py", line 452, in spawnv_passfds
    return _posixsubprocess.fork_exec(
KeyboardInterrupt

Restarting training from last epoch ...
No matching checkpoint file found
Training crashed at epoch 1
Traceback for the error!
Traceback (most recent call last):
  File "/home/yutong/zheng/projects/DBSR/trainers/base_trainer.py", line 71, in train
    self.train_epoch()
  File "/home/yutong/zheng/projects/DBSR/trainers/simple_trainer.py", line 96, in train_epoch
    self.cycle_dataset(loader)
  File "/home/yutong/zheng/projects/DBSR/trainers/simple_trainer.py", line 66, in cycle_dataset
    for i, data in enumerate(loader, 1):
  File "/home/yutong/anaconda3/envs/dbsr/lib/python3.8/site-packages/torch/utils/data/dataloader.py", line 444, in __iter__
    return self._get_iterator()
  File "/home/yutong/anaconda3/envs/dbsr/lib/python3.8/site-packages/torch/utils/data/dataloader.py", line 390, in _get_iterator
    return _MultiProcessingDataLoaderIter(self)
  File "/home/yutong/anaconda3/envs/dbsr/lib/python3.8/site-packages/torch/utils/data/dataloader.py", line 1077, in __init__
    w.start()
  File "/home/yutong/anaconda3/envs/dbsr/lib/python3.8/multiprocessing/process.py", line 121, in start
    self._popen = self._Popen(self)
  File "/home/yutong/anaconda3/envs/dbsr/lib/python3.8/multiprocessing/context.py", line 224, in _Popen
    return _default_context.get_context().Process._Popen(process_obj)
  File "/home/yutong/anaconda3/envs/dbsr/lib/python3.8/multiprocessing/context.py", line 284, in _Popen
    return Popen(process_obj)
  File "/home/yutong/anaconda3/envs/dbsr/lib/python3.8/multiprocessing/popen_spawn_posix.py", line 32, in __init__
    super().__init__(process_obj)
  File "/home/yutong/anaconda3/envs/dbsr/lib/python3.8/multiprocessing/popen_fork.py", line 19, in __init__
    self._launch(process_obj)
  File "/home/yutong/anaconda3/envs/dbsr/lib/python3.8/multiprocessing/popen_spawn_posix.py", line 58, in _launch
    self.pid = util.spawnv_passfds(spawn.get_executable(),
  File "/home/yutong/anaconda3/envs/dbsr/lib/python3.8/multiprocessing/util.py", line 452, in spawnv_passfds
    return _posixsubprocess.fork_exec(
KeyboardInterrupt

Restarting training from last epoch ...
No matching checkpoint file found
Training crashed at epoch 1
Traceback for the error!
Traceback (most recent call last):
  File "/home/yutong/zheng/projects/DBSR/trainers/base_trainer.py", line 71, in train
    self.train_epoch()
  File "/home/yutong/zheng/projects/DBSR/trainers/simple_trainer.py", line 96, in train_epoch
    self.cycle_dataset(loader)
  File "/home/yutong/zheng/projects/DBSR/trainers/simple_trainer.py", line 66, in cycle_dataset
    for i, data in enumerate(loader, 1):
  File "/home/yutong/anaconda3/envs/dbsr/lib/python3.8/site-packages/torch/utils/data/dataloader.py", line 444, in __iter__
    return self._get_iterator()
  File "/home/yutong/anaconda3/envs/dbsr/lib/python3.8/site-packages/torch/utils/data/dataloader.py", line 390, in _get_iterator
    return _MultiProcessingDataLoaderIter(self)
  File "/home/yutong/anaconda3/envs/dbsr/lib/python3.8/site-packages/torch/utils/data/dataloader.py", line 1077, in __init__
    w.start()
  File "/home/yutong/anaconda3/envs/dbsr/lib/python3.8/multiprocessing/process.py", line 121, in start
    self._popen = self._Popen(self)
  File "/home/yutong/anaconda3/envs/dbsr/lib/python3.8/multiprocessing/context.py", line 224, in _Popen
    return _default_context.get_context().Process._Popen(process_obj)
  File "/home/yutong/anaconda3/envs/dbsr/lib/python3.8/multiprocessing/context.py", line 284, in _Popen
    return Popen(process_obj)
  File "/home/yutong/anaconda3/envs/dbsr/lib/python3.8/multiprocessing/popen_spawn_posix.py", line 32, in __init__
    super().__init__(process_obj)
  File "/home/yutong/anaconda3/envs/dbsr/lib/python3.8/multiprocessing/popen_fork.py", line 19, in __init__
    self._launch(process_obj)
  File "/home/yutong/anaconda3/envs/dbsr/lib/python3.8/multiprocessing/popen_spawn_posix.py", line 58, in _launch
    self.pid = util.spawnv_passfds(spawn.get_executable(),
  File "/home/yutong/anaconda3/envs/dbsr/lib/python3.8/multiprocessing/util.py", line 452, in spawnv_passfds
    return _posixsubprocess.fork_exec(
KeyboardInterrupt

Restarting training from last epoch ...
No matching checkpoint file found
Training crashed at epoch 1
Traceback for the error!
Traceback (most recent call last):
  File "/home/yutong/zheng/projects/DBSR/trainers/base_trainer.py", line 71, in train
    self.train_epoch()
  File "/home/yutong/zheng/projects/DBSR/trainers/simple_trainer.py", line 96, in train_epoch
    self.cycle_dataset(loader)
  File "/home/yutong/zheng/projects/DBSR/trainers/simple_trainer.py", line 66, in cycle_dataset
    for i, data in enumerate(loader, 1):
  File "/home/yutong/anaconda3/envs/dbsr/lib/python3.8/site-packages/torch/utils/data/dataloader.py", line 444, in __iter__
    return self._get_iterator()
  File "/home/yutong/anaconda3/envs/dbsr/lib/python3.8/site-packages/torch/utils/data/dataloader.py", line 390, in _get_iterator
    return _MultiProcessingDataLoaderIter(self)
  File "/home/yutong/anaconda3/envs/dbsr/lib/python3.8/site-packages/torch/utils/data/dataloader.py", line 1077, in __init__
    w.start()
  File "/home/yutong/anaconda3/envs/dbsr/lib/python3.8/multiprocessing/process.py", line 121, in start
    self._popen = self._Popen(self)
  File "/home/yutong/anaconda3/envs/dbsr/lib/python3.8/multiprocessing/context.py", line 224, in _Popen
    return _default_context.get_context().Process._Popen(process_obj)
  File "/home/yutong/anaconda3/envs/dbsr/lib/python3.8/multiprocessing/context.py", line 284, in _Popen
    return Popen(process_obj)
  File "/home/yutong/anaconda3/envs/dbsr/lib/python3.8/multiprocessing/popen_spawn_posix.py", line 32, in __init__
    super().__init__(process_obj)
  File "/home/yutong/anaconda3/envs/dbsr/lib/python3.8/multiprocessing/popen_fork.py", line 19, in __init__
    self._launch(process_obj)
  File "/home/yutong/anaconda3/envs/dbsr/lib/python3.8/multiprocessing/popen_spawn_posix.py", line 58, in _launch
    self.pid = util.spawnv_passfds(spawn.get_executable(),
  File "/home/yutong/anaconda3/envs/dbsr/lib/python3.8/multiprocessing/util.py", line 452, in spawnv_passfds
    return _posixsubprocess.fork_exec(
KeyboardInterrupt

Restarting training from last epoch ...
Finished training!
